<?xml version="1.0"?>
<robot xmlns:xacro="http://www.ros.org/wiki/xacro" name="vikram">
    <xacro:include filename="$(find my_bot1)/models/vikram/model_plugins.xacro" />
    <link name="base">
        <inertial>
            <origin xyz="0.032080873 0.005220866 0.017540908" />
            <mass value="40.00000000" />
            <inertia ixx="0.0422305911" ixy="0.0000134527" ixz="-0.0095850904" iyy="0.0603116526"
                iyz="-0.0000275548" izz="0.0316155243" />
        </inertial>
        <geometry>
            <mesh filename="package://my_bot1/models/meshes/body/bot2.dae" scale="0.1 0.1 0.1" />
            <origin xyz="0.0 0.0 -0.05" rpy="0.0 0.0 0.0" />

        </geometry>

        <collision name='base_collision'>
            <pose xyz="0.0 0.0 0.0" rpy="0.0 0.0 0.0" />
            <geometry>
                <mesh filename="package://my_bot1/models/meshes/body/bot2.dae" scale="0.1 0.1 0.1" />
            </geometry>
        </collision>

        <visual name="base_visual">
            <pose xyz="0.0 0.0 0.0" rpy="0.0 0.0 0.0" />
            <geometry>
                <mesh filename="package://my_bot1/models/meshes/body/bot2.dae" scale="0.1 0.1 0.1" />
            </geometry>
        </visual>
    </link>


    <link
        name="castor_wheel">
        <inertial>
            <origin xyz="0.002502250 -0.000165115 -0.005096490" />
            <mass value="2.00000000" />
            <inertia ixx="0.0000267084" ixy="-0.0000001349" ixz="0.0000009483" iyy="0.0000254837"
                iyz="-0.0000000364" izz="0.0000263221" />
        </inertial>
        <visual>
            <origin xyz="0 0 0" rpy="0.0 0.0 0.0" />
            <geometry>
                <mesh filename="package://my_bot1/models/meshes/wheels/castors1.dae"
                    scale="0.1 0.1 0.1" />
            </geometry>
        </visual>
        <collision name='castorwheel'>
            <geometry>
                <mesh filename="package://my_bot1/models/meshes/wheels/castors1.dae"
                    scale="0.1 0.1 0.1" />
            </geometry>
        </collision>
        <geometry>
            <mesh filename="package://my_bot1/models/meshes/wheels/castors1.dae" scale="0.1 0.1 0.1" />
        </geometry>
    </link>

    <link
        name="right_wheel">
        <inertial>
            <origin xyz="0.000328500 0.000123296 -0.000291822" />
            <mass value="5.00000000" />
            <inertia ixx="0.0002467805" ixy="-0.00000000" ixz="-0.0000000001" iyy="0.0004221351"
                iyz="0.00000000" izz="0.0002467815" />
        </inertial>
        <visual>
            <pose xyz="0 -0.0323 0" rpy="0.0 0.0 0.0" />
            <geometry>
                <mesh filename="package://my_bot1/models/meshes/wheels/tyre1.dae"
                    scale="0.1 0.1 0.1" />
            </geometry>
        </visual>
        <collision name="right_wheel_collision">
            <pose xyz="0 -0.0323 0" rpy="-1.57 0.0 0.0" />
            <geometry>
                <mesh filename="package://my_bot1/models/meshes/wheels/tyre1.dae"
                    scale="0.1 0.1 0.1" />
            </geometry>
            <surface>
                <friction>
                    <ode>
                        <mu>100000.0</mu>
                        <mu2>100000.0</mu2>
                        <fdir1>0 0 0</fdir1>
                        <slip1>0</slip1>
                        <slip2>0</slip2>
                    </ode>
                </friction>
            </surface>
        </collision>
    </link>
    <link
        name="left_wheel">
        <inertial>
            <origin xyz="0.000328500 0.000123296 -0.000291822" />
            <mass value="5.00000000" />
            <inertia ixx="0.0002467805" ixy="-0.00000000" ixz="-0.0000000001" iyy="0.0004221351"
                iyz="0.00000000" izz="0.0002467815" />
        </inertial>

        <visual>
            <pose xyz="0 0.0323 0" rpy="0.0 0.0 0.0" />
            <geometry>
                <mesh filename="package://my_bot1/models/meshes/wheels/tyre1.dae"
                    scale="0.1 0.1 0.1" />
            </geometry>
        </visual>
        <collision name="left_wheel_collision">
            <pose xyz="0 0.0323 0" rpy="-1.57 0.0 0.0" />
            <geometry>
                <mesh filename="package://my_bot1/models/meshes/wheels/tyre1.dae"
                    scale="0.1 0.1 0.1" />
            </geometry>
            <surface>
                <friction>
                    <ode>
                        <mu>100000.0</mu>
                        <mu2>100000.0</mu2>
                        <fdir1>0 0 0</fdir1>
                        <slip1>0</slip1>
                        <slip2>0</slip2>
                    </ode>
                </friction>
            </surface>
        </collision>
    </link>
    <link name="stereo_camera_link">
        <pose xyz="0.073 0 0.118" rpy="0.0 0.45 0.0" />
    </link>


    <joint name="right_wheel_base_joint" type="continuous">
        <origin xyz="0.0 -0.0323 0" rpy="0.0 0.0 0.0" />
        <parent link="base" />
        <child link="right_wheel" />
        <axis xyz="0.0 1.0 0.0" />
    </joint>

    <joint name="castor_base_joint"
        type="fixed">
        <origin xyz="0.048 0.0 0.002" rpy="0.0 0.0 0.0" />
        <parent link="base" />
        <child link="castor_wheel" />

    </joint>
    <joint name="left_wheel_base_joint"
        type="continuous">
        <origin xyz="0 0.0323 0" rpy="0.0 0.0 0.0" />
        <parent link="base" />
        <child link="left_wheel" />
        <axis xyz="0.0 1.0 0.0" />
    </joint>


    <joint name="stereo_camera_joint" type="fixed">
        <origin xyz="0.073 0 0.118" rpy="0.0 0.45 0.0" />
        <parent link="base" />
        <child link="stereo_camera_link" />
    </joint>


</robot>